# Error-handling-with-promises
Error handling with promises in JavaScript is crucial to ensure that your asynchronous code behaves as expected. Promises provide a clean and structured way to handle both successful and failed asynchronous operations. Here's a basic overview of error handling with promises:

Error handling with promises in JavaScript is crucial to ensure that your asynchronous code behaves as expected. Promises provide a clean and structured way to handle both successful and failed asynchronous operations. Here's a basic overview of error handling with promises:

**1). Promise Structure:**
Promises typically have a structure like this:

const myPromise = new Promise((resolve, reject) => {
  // Asynchronous operation
  // If successful, call resolve(value)
  // If an error occurs, call reject(error)
});


**2). Handling Success:**
Use the .then() method to handle the success case:

myPromise
  .then((result) => {
    // Handle success
    console.log(result);
  })
  .catch((error) => {
    // Handle errors
    console.error(error);
  });
In this example, if the promise resolves successfully, the function inside .then() will be executed. If an error occurs during the promise execution, the function inside .catch() will be executed.

**3). Handling Errors:**
The reject() function is used to trigger error handling. When a promise is rejected, the control flow jumps to the nearest .catch() block:
const myPromise = new Promise((resolve, reject) => {
  // Asynchronous operation
  if (/* operation successful */) {
    resolve('Success!');
  } else {
    reject(new Error('Something went wrong.'));
  }
});

**4).Chaining Promises:**
You can chain multiple .then() blocks to perform a sequence of asynchronous operations. If an error occurs at any stage, the control flow will skip to the nearest .catch() block:

myPromise
  .then((result) => {
    // First operation successful
    return anotherAsyncOperation(result);
  })
  .then((result) => {
    // Second operation successful
    console.log(result);
  })
  .catch((error) => {
    // Handle errors in any of the previous steps
    console.error(error);
  });
  
**5).Returning Promises:**
You can also return a new promise from within a .then() block to continue the chain:
myPromise

  .then((result) => {
    // First operation successful
    return new Promise((resolve, reject) => {
      // Another asynchronous operation
      if (/* operation successful */) {
        resolve('Success!');
      } else {
        reject(new Error('Another error occurred.'));
      }
    });
  })
  .then((result) => {
    // Second operation successful
    console.log(result);
  })
  .catch((error) => {
    // Handle errors in any of the previous steps
    console.error(error);
  });

By following these principles, you can create robust and maintainable asynchronous code with promises, ensuring that errors are handled appropriately at each step of the execution.
